File: ASEN1022_Lab/Brittle
%	Crosshead Position (in)	Load (lbs)	Extensometer Position (in)	3/22/2018	12:32 PM
0.00338150	6.85794544	-0.00084272
0.00387622	9.08362865	-0.00082940
0.00437089	10.67952824	-0.00081444
0.00486556	11.29189301	-0.00079885
0.00536514	10.93278217	-0.00079179
0.00587214	12.04763412	-0.00078198
0.00637420	14.25321770	-0.00077716
0.00687135	14.41267395	-0.00078377
0.00737097	16.62093735	-0.00077432
0.00787055	17.54551315	-0.00077942
0.00837507	17.34317970	-0.00077960
0.00887470	18.59738731	-0.00078028
0.00937185	20.71453285	-0.00078857
0.00986652	22.61192513	-0.00078878
0.01036610	26.43082809	-0.00078833
0.01087310	29.70704460	-0.00080690
0.01137515	31.13142967	-0.00082600
0.01186983	33.99627686	-0.00083527
0.01236450	37.02861786	-0.00085688
0.01286660	39.27708054	-0.00087991
0.01337108	43.50065613	-0.00090012
0.01387318	47.87698364	-0.00092146
0.01437033	51.67980576	-0.00094292
0.01486990	62.25615692	-0.00095394
0.01537196	76.66749573	-0.00095600
0.01587158	92.28345490	-0.00097260
0.01637611	117.82052612	-0.00097764
0.01687326	151.57426453	-0.00096014
0.01736793	176.88757324	-0.00093573
0.01786508	192.93231201	-0.00092095
0.01836960	207.62773132	-0.00090116
0.01887409	220.79959106	-0.00086555
0.01937123	232.82980347	-0.00081539
0.01986348	244.46339417	-0.00077617
0.02036553	254.92718506	-0.00076386
0.02087253	266.22711182	-0.00073540
0.02137459	276.20315552	-0.00071660
0.02187173	284.46270752	-0.00069168
0.02237131	294.59555054	-0.00067365
0.02287336	304.41079712	-0.00065809
0.02337546	312.39028931	-0.00064453
0.02387504	322.52310181	-0.00061876
0.02437219	332.04223633	-0.00060880
0.02486686	340.72387695	-0.00058284
0.02536649	352.25561523	-0.00058815
0.02587101	364.66638184	-0.00056753
0.02637554	375.30169678	-0.00055769
0.02687264	387.41094971	-0.00054052
0.02736489	400.28268433	-0.00053871
0.02786694	412.92657471	-0.00053188
0.02837147	427.52148437	-0.00051349
0.02887352	441.95294189	-0.00049865
0.02937067	454.50708008	-0.00047308
0.02987272	470.15118408	-0.00047132
0.03037235	485.57150269	-0.00045460
0.03087440	499.67599487	-0.00043318
0.03137645	516.35858154	-0.00041968
0.03187360	532.19830322	-0.00039974
0.03236827	546.83074951	-0.00039303
0.03286789	563.86840820	-0.00036770
0.03336995	581.32012939	-0.00035855
0.03387695	597.07678223	-0.00033408
0.03437162	614.55261230	-0.00031650
0.03486382	632.12628174	-0.00029534
0.03536592	648.43231201	-0.00028139
0.03587288	667.84039307	-0.00026014
0.03637493	686.50207520	-0.00024059
0.03687208	703.43255615	-0.00022152
0.03736923	722.87677002	-0.00020844
0.03787128	742.05438232	-0.00021231
0.03837338	760.01794434	-0.00016460
0.03887543	780.56903076	-0.00013992
0.03937258	800.27722168	-0.00012776
0.03986725	818.57849121	-0.00009471
0.04036683	838.95941162	-0.00007954
0.04087136	859.81866455	-0.00004807
0.04137341	880.16198730	-0.00002971
0.04187056	900.67285156	-0.00001276
0.04236523	921.24401855	0.00001514
0.04286486	940.90130615	0.00004023
0.04337186	963.02282715	0.00006878
0.04387391	984.45288086	0.00008219
0.04437106	1004.04724121	0.00011751
0.04487064	1025.65148926	0.00014427
0.04537269	1046.88854980	0.00016892
0.04587231	1067.06445312	0.00019151
0.04637684	1089.44323730	0.00021264
0.04687399	1110.42443848	0.00024083
0.04736866	1129.82312012	0.00026533
0.04786581	1151.54260254	0.00030386
0.04837034	1173.98034668	0.00034317
0.04887487	1194.42956543	0.00035730
0.04937197	1215.76855469	0.00039470
0.04986421	1236.61840820	0.00041765
0.05036626	1256.77954102	0.00045669
0.05087079	1278.48291016	0.00047824
0.05137532	1300.41418457	0.00050858
0.05186999	1319.93750000	0.00054720
0.05236962	1341.66235352	0.00058404
0.05287414	1363.07238770	0.00060093
0.05337372	1382.76708984	0.00066638
0.05387577	1404.80688477	0.00068113
0.05437292	1425.16906738	0.00072780
0.05486760	1443.87902832	0.00076598
0.05536474	1464.21704102	0.00078461
0.05587175	1484.86181641	0.00083542
0.05637627	1504.26318359	0.00086716
0.05687095	1524.65075684	0.00091654
0.05736562	1543.78283691	0.00091842
0.05786524	1562.60803223	0.00098434
0.05837220	1583.42431641	0.00103277
0.05887425	1603.90173340	0.00106353
0.05937140	1621.48608398	0.00111639
0.05987103	1641.50659180	0.00114343
0.06037308	1661.25097656	0.00119591
0.06087513	1679.25073242	0.00124088
0.06137475	1697.38574219	0.00129727
0.06187433	1714.95410156	0.00133181
0.06236900	1731.21862793	0.00138360
0.06286615	1749.05627441	0.00142843
0.06337316	1767.33740234	0.00149006
0.06387521	1783.52014160	0.00152260
0.06437235	1801.14868164	0.00159112
0.06486455	1817.75488281	0.00164175
0.06536417	1832.86840820	0.00168747
0.06587361	1851.76599121	0.00174937
0.06637324	1868.56237793	0.00180605
0.06687281	1883.16809082	0.00187045
0.06736996	1899.73669434	0.00193638
0.06787201	1917.07727051	0.00200695
0.06837411	1931.31567383	0.00206611
0.06887616	1947.77856445	0.00213766
0.06937331	1963.18005371	0.00220031
0.06986798	1976.89062500	0.00228536
0.07036756	1992.17297363	0.00233889
0.07086966	2008.19494629	0.00243223
0.07137419	2022.00061035	0.00250682
0.07187129	2036.43334961	0.00261438
0.07236601	2050.31542969	0.00267267
0.07286559	2063.05053711	0.00276816
0.07337011	2078.01391602	0.00284070
0.07387464	2092.32202148	0.00294393
0.07436932	2103.44238281	0.00301778
0.07486894	2116.95458984	0.00312671
0.07537099	2130.30859375	0.00322872
0.07587305	2141.46118164	0.00331917
0.07637757	2154.08227539	0.00341395
0.07677627	-0.81067955	-0.04671620
0.07677136	-2.33288097	-0.04677515