File: ASEN1022_Lab/Ductile
%	Crosshead Position (in)	Load (lbs)	Extensometer Position (in)	3/19/2018	1:26 PM
-0.00000243	5.93604946	-0.00502451
0.00492455	37.46276855	-0.00497282
0.00991561	126.66429901	-0.00491446
0.01491894	456.89624023	-0.00464988
0.01991981	603.13879395	-0.00445315
0.02491577	737.30688477	-0.00428605
0.02991910	885.65985107	-0.00412551
0.03492244	1048.98034668	-0.00395177
0.03991840	1228.83056641	-0.00376162
0.04492179	1422.41271973	-0.00357294
0.04992265	1625.04370117	-0.00337805
0.05491370	1838.15991211	-0.00313063
0.05991704	2060.28344727	-0.00292297
0.06492281	2286.31567383	-0.00260836
0.06991634	2516.04345703	-0.00234345
0.07491968	2746.39697266	-0.00206745
0.07992054	2968.09301758	-0.00178087
0.08491402	3174.89794922	-0.00150657
0.08991984	3351.81372070	-0.00119975
0.09492075	3486.72680664	-0.00076744
0.09991670	3584.56982422	0.00020030
0.10492004	3648.94848633	0.00208592
0.10992338	3687.26733398	0.00465542
0.11082413	3554.12695312	0.00628342
0.11572902	3728.29711914	0.00628711
0.12073483	3748.06445312	0.00628118
0.12573080	3767.95483398	0.00628008
0.13072918	3786.72778320	0.00627987
0.13573252	3807.53076172	0.00628625
0.14072604	3824.85766602	0.00628389
0.14573182	3841.14501953	0.00628068
0.15073515	3859.98364258	0.00628181
0.15573111	3875.30493164	0.00629230
0.16072954	3888.57446289	0.00628208
0.16573289	3904.19580078	0.00628380
0.17072637	3916.61059570	0.00628315
0.17572975	3927.93994141	0.00628780
0.18073308	3940.87060547	0.00628705
0.18572906	3951.54077148	0.00629179
0.19073239	3961.14575195	0.00629179
0.19573572	3971.64038086	0.00629236
0.20072673	3979.85839844	0.00628854
0.20573008	3986.38671875	0.00628667
0.21073346	3995.59350586	0.00628977
0.21572942	4002.47827148	0.00629048
0.22073275	4006.60546875	0.00628926
0.22573362	4012.08984375	0.00629194
0.23072468	4017.29956055	0.00628306
0.23572801	4019.04833984	0.00628914
0.24073377	4023.71142578	0.00628455
0.24572730	4025.91577148	0.00629090
0.25073063	4026.36718750	0.00628637
0.25573400	4027.94702148	0.00629203
0.26072994	4027.46191406	0.00629430
0.26572838	4025.11157227	0.00628714
0.27073413	4022.80957031	0.00628583
0.27572766	4016.64575195	0.00628443
0.28073102	4007.37329102	0.00629331
0.28573436	3996.87182617	0.00628577
0.29072782	3979.02075195	0.00629337
0.29572868	3953.36718750	0.00629024
0.30073452	3924.07958984	0.00629617
0.30573046	3886.01782227	0.00629412
0.31073380	3840.30224609	0.00628795
0.31573471	3785.30737305	0.00629099
0.32072821	3719.17187500	0.00629179
0.32573155	3630.39257812	0.00629313
0.33073488	3447.96557617	0.00628857
0.33245027	-2.06354737	0.00633161
0.33244780	-2.99214387	0.00633191